<mujoco model="000">
  <compiler angle="radian" meshdir="../meshes/"/>

  <asset>
    <mesh name="base_link" file="base_link.STL"/>
    <mesh name="Link_ZQ1" file="Link_ZQ1.STL"/>
    <mesh name="Link_ZQ2" file="Link_ZQ2.STL"/>
    <mesh name="Link_ZQ3" file="Link_ZQ3.STL"/>
    <mesh name="Link_ZQ4" file="Link_ZQ4.STL"/>
    <mesh name="Link_ZQ5" file="Link_ZQ5.STL"/>
    <mesh name="Link_ZH1" file="Link_ZH1.STL"/>
    <mesh name="Link_ZH2" file="Link_ZH2.STL"/>
    <mesh name="Link_ZH3" file="Link_ZH3.STL"/>
    <mesh name="Link_ZH4" file="Link_ZH4.STL"/>
    <mesh name="Link_ZH5" file="Link_ZH5.STL"/>
    <mesh name="Link_YQ1" file="Link_YQ1.STL"/>
    <mesh name="Link_YQ2" file="Link_YQ2.STL"/>
    <mesh name="Link_YQ3" file="Link_YQ3.STL"/>
    <mesh name="Link_YQ4" file="Link_YQ4.STL"/>
    <mesh name="Link_YQ5" file="Link_YQ5.STL"/>
    <mesh name="Link_YH1" file="Link_YH1.STL"/>
    <mesh name="Link_YH2" file="Link_YH2.STL"/>
    <mesh name="Link_YH3" file="Link_YH3.STL"/>
    <mesh name="Link_YH4" file="Link_YH4.STL"/>
    <mesh name="Link_YH5" file="Link_YH5.STL"/>
  </asset>

  <worldbody>
    <body name="base_link" pos="0 0 0.6">
      <geom type="mesh" contype="0" conaffinity="0" group="1" density="0" rgba="1 1 1 1" mesh="base_link"/>
      <joint name="floating_base_joint" type="free" limited="false" actuatorfrclimited="false"/>
      <geom size="0.12 0.07 0.04" pos="0 0 -0.04" type="box" rgba="1 1 1 1"/>
      <geom pos="0.113 0.044 0" type="mesh" contype="0" conaffinity="0" group="1" density="0" rgba="0.898039 0.917647 0.929412 1" mesh="Link_ZQ1"/>
      <geom pos="-0.113 0.044 0" type="mesh" contype="0" conaffinity="0" group="1" density="0" rgba="0.898039 0.917647 0.929412 1" mesh="Link_ZH1"/>
      <geom pos="0.113 -0.044 0" type="mesh" contype="0" conaffinity="0" group="1" density="0" rgba="1 1 1 1" mesh="Link_YQ1"/>
      <geom pos="-0.113 -0.044 0" quat="-3.67321e-06 0 0 -1" type="mesh" contype="0" conaffinity="0" group="1" density="0" rgba="1 1 1 1" mesh="Link_YH1"/>
      <site name="imu" pos="-0.0 0 0." />
      <body name="Link_ZQ2" pos="0.113 0.044 -0.04">
        <inertial pos="0.0663019 -0.00460558 1.61687e-08" quat="0.500665 0.500655 0.499335 0.499344" mass="0.368364" diaginertia="0.000175167 0.000157091 0.000147643"/>
        <joint name="joint_ZQ2" pos="0 0 0" axis="1 0 0" range="-0.79 0.79"/>
        <geom type="mesh" contype="0" conaffinity="0" group="1" density="0" rgba="0.898039 0.917647 0.929412 1" mesh="Link_ZQ2"/>
        <geom size="0.03 0.025" pos="0.07 0 0" quat="0.707388 0.706825 0 0" type="cylinder" rgba="0.898039 0.917647 0.929412 1"/>
        <body name="Link_ZQ3" pos="0.067 0 0">
          <inertial pos="-5.91352e-05 0.059451 -0.00768867" quat="0.707354 9.9172e-06 -9.92415e-06 0.706859" mass="0.538002" diaginertia="0.000517655 0.000436232 0.000212184"/>
          <joint name="joint_ZQ3" pos="0 0 0" axis="0 1 0" range="-3.14 3.14"/>
          <geom type="mesh" contype="0" conaffinity="0" group="1" density="0" rgba="1 1 1 1" mesh="Link_ZQ3"/>
          <geom size="0.03 0.025" pos="0 0.07 0" quat="0.707388 0.706825 0 0" type="cylinder" rgba="1 1 1 1"/>
          <geom size="0.0175 0.005 0.05" pos="0 0.09 -0.082" type="box" rgba="1 1 1 1"/>
          <body name="Link_ZQ4" pos="0 0.0885 -0.15">
            <inertial pos="-1.46154e-08 3.41698e-07 -0.108034" quat="1 0 0 -9.95816e-05" mass="0.0802946" diaginertia="0.000248142 0.000247115 9.65894e-06"/>
            <joint name="joint_ZQ4" pos="0 0 0" axis="0 1 0" range="-3.14 3.14"/>
            <geom type="mesh" contype="0" conaffinity="0" group="1" density="0" rgba="1 1 1 1" mesh="Link_ZQ4"/>
            <geom type="mesh" rgba="1 1 1 1" mesh="Link_ZQ4"/>
            <geom pos="0 0 -0.16" quat="1 0 0 0" type="mesh" contype="0" conaffinity="0" group="1" density="0" rgba="1 1 1 1" mesh="Link_ZQ5"/>
            <geom pos="0 0 -0.16" quat="1 0 0 0" type="mesh" rgba="1 1 1 1" mesh="Link_ZQ5"/>
          </body>
        </body>
      </body>
      <body name="Link_ZH2" pos="-0.113 0.044 -0.04">
        <inertial pos="-0.0663019 -0.00460559 -1.58356e-08" quat="0.499344 0.499335 0.500655 0.500665" mass="0.368364" diaginertia="0.000175167 0.000157091 0.000147643"/>
        <joint name="joint_ZH2" pos="0 0 0" axis="1 0 0" range="-0.79 0.79"/>
        <geom type="mesh" contype="0" conaffinity="0" group="1" density="0" rgba="1 1 1 1" mesh="Link_ZH2"/>
        <geom size="0.03 0.025" pos="-0.07 0 0" quat="0.707388 0.706825 0 0" type="cylinder" rgba="1 1 1 1"/>
        <body name="Link_ZH3" pos="-0.067 0 0">
          <inertial pos="-7.60103e-05 0.059451 -0.00768873" quat="0.707151 9.8267e-06 -9.82792e-06 0.707063" mass="0.538002" diaginertia="0.000517655 0.000436232 0.000212184"/>
          <joint name="joint_ZH3" pos="0 0 0" axis="0 1 0" range="-3.14 3.14"/>
          <geom type="mesh" contype="0" conaffinity="0" group="1" density="0" rgba="1 1 1 1" mesh="Link_ZH3"/>
          <geom size="0.03 0.025" pos="0 0.07 0" quat="0.707388 0.706825 0 0" type="cylinder" rgba="1 1 1 1"/>
          <geom size="0.0175 0.005 0.05" pos="0 0.09 -0.082" type="box" rgba="1 1 1 1"/>
          <body name="Link_ZH4" pos="0 0.0885 -0.15">
            <inertial pos="-1.46154e-08 3.41698e-07 -0.108034" quat="1 0 0 -9.95816e-05" mass="0.0802946" diaginertia="0.000248142 0.000247115 9.65894e-06"/>
            <joint name="joint_ZH4" pos="0 0 0" axis="0 1 0" range="-3.14 3.14"/>
            <geom type="mesh" contype="0" conaffinity="0" group="1" density="0" rgba="1 1 1 1" mesh="Link_ZH4"/>
            <geom type="mesh" rgba="1 1 1 1" mesh="Link_ZH4"/>
            <geom pos="0 0 -0.16" quat="1 0 0 0" type="mesh" contype="0" conaffinity="0" group="1" density="0" rgba="1 1 1 1" mesh="Link_ZH5"/>
            <geom pos="0 0 -0.16" quat="1 0 0 0" type="mesh" rgba="1 1 1 1" mesh="Link_ZH5"/>
          </body>
        </body>
      </body>
      <body name="Link_YQ2" pos="0.113 -0.044 -0.04">
        <inertial pos="0.0663019 0.00460559 -1.58356e-08" quat="0.499335 0.499344 0.500665 0.500655" mass="0.368364" diaginertia="0.000175167 0.000157091 0.000147643"/>
        <joint name="joint_YQ2" pos="0 0 0" axis="1 0 0" range="-0.79 0.79"/>
        <geom type="mesh" contype="0" conaffinity="0" group="1" density="0" rgba="1 1 1 1" mesh="Link_YQ2"/>
        <geom size="0.03 0.025" pos="0.07 0 0" quat="0.707388 0.706825 0 0" type="cylinder" rgba="1 1 1 1"/>
        <body name="Link_YQ3" pos="0.067 0 0">
          <inertial pos="-5.85993e-05 -0.0594509 -0.00768937" quat="0.706858 8.2122e-06 -8.20643e-06 0.707355" mass="0.538004" diaginertia="0.000517683 0.000436261 0.000212184"/>
          <joint name="joint_YQ3" pos="0 0 0" axis="0 1 0" range="-3.14 3.14"/>
          <geom type="mesh" contype="0" conaffinity="0" group="1" density="0" rgba="1 1 1 1" mesh="Link_YQ3"/>
          <geom size="0.03 0.025" pos="0 -0.07 0" quat="0.707388 0.706825 0 0" type="cylinder" rgba="1 1 1 1"/>
          <geom size="0.0175 0.005 0.05" pos="0 -0.09 -0.082" type="box" rgba="1 1 1 1"/>
          <body name="Link_YQ4" pos="0 -0.0885 -0.15">
            <inertial pos="-1.46154e-08 3.41698e-07 -0.108034" quat="1 0 0 -9.95816e-05" mass="0.0802946" diaginertia="0.000248142 0.000247115 9.65894e-06"/>
            <joint name="joint_YQ4" pos="0 0 0" axis="0 1 0" range="-3.14 3.14"/>
            <geom type="mesh" contype="0" conaffinity="0" group="1" density="0" rgba="1 1 1 1" mesh="Link_YQ4"/>
            <geom type="mesh" rgba="1 1 1 1" mesh="Link_YQ4"/>
            <geom pos="0 0 -0.16" quat="1 0 0 0" type="mesh" contype="0" conaffinity="0" group="1" density="0" rgba="1 1 1 1" mesh="Link_YQ5"/>
            <geom pos="0 0 -0.16" quat="1 0 0 0" type="mesh" rgba="1 1 1 1" mesh="Link_YQ5"/>
          </body>
        </body>
      </body>
      <!-- quat="0. 0.707 0.0 0.707 -->
      <body name="Link_YH2" pos="-0.113 -0.044 -0.04" quat="0. 0.707 0.0 0.707">  
        <inertial pos="-1.58357e-08 -0.00460558 0.0663019" quat="0.707106 0.000927553 -0.00094045 0.707106" mass="0.368364" diaginertia="0.000175167 0.000157091 0.000147643"/>
        <joint name="joint_YH2" pos="0 0 0" axis="0 0 -1" range="-0.79 0.79"/>
        <geom type="mesh" contype="0" conaffinity="0" group="1" density="0" rgba="0.898039 0.917647 0.929412 1" mesh="Link_YH2"/>
        <geom size="0.03 0.025" pos="0 0 0.07" quat="0.707388 0.706825 0 0" type="cylinder" rgba="0.898039 0.917647 0.929412 1"/>
        <body name="Link_YH3" pos="0 0 0.067" quat="0.5 0.5 0.5 0.5">
          <inertial pos="7.5716e-05 0.00768936 0.0594509" quat="0.499975 0.499963 -0.500025 0.500037" mass="0.538004" diaginertia="0.000517683 0.000436261 0.000212184"/>
          <joint name="joint_YH3" pos="0 0 0" axis="0 0 -1" range="-3.14 3.14"/>
          <geom type="mesh" contype="0" conaffinity="0" group="1" density="0" rgba="1 1 1 1" mesh="Link_YH3"/>
          <geom size="0.03 0.025" pos="0 0 0.07" type="cylinder" rgba="1 1 1 1"/>
          <geom size="0.0175 0.005 0.05" pos="0 0.082 0.09" quat="0.707388 0.706825 0 0" type="box" rgba="1 1 1 1"/>
          <body name="Link_YH4" pos="0 0.15 0.0885" quat="0.7 0.7 0.0 0.">
            <inertial pos="-1.46154e-08 3.41698e-07 -0.108034" quat="1 0 0 -9.95816e-05" mass="0.0802946" diaginertia="0.000248142 0.000247115 9.65894e-06"/>
            <joint name="joint_YH4" pos="0 0 0" axis="0 -1 0" range="-3.14 3.14"/>
            <geom type="mesh" contype="0" conaffinity="0" group="1" density="0" rgba="1 1 1 1" mesh="Link_YH4"/>
            <geom type="mesh" rgba="1 1 1 1" mesh="Link_YH4"/>
            <geom pos="0 0 -0.16" quat="1 0 0 0" type="mesh" contype="0" conaffinity="0" group="1" density="0" rgba="1 1 1 1" mesh="Link_YH5"/>
            <geom pos="0 0 -0.16" quat="1 0 0 0" type="mesh" rgba="1 1 1 1" mesh="Link_YH5"/>
          </body>
        </body>
      </body>
    </body>
  </worldbody>

  <!-- <actuator>
    <position joint="joint_ZQ2" kp="10.0" kv="0.1" ctrlrange="-1.04 1.04"/>
    <position joint="joint_YQ2" kp="10.0" kv="0.1" ctrlrange="-1.04 1.04"/>
    <position joint="joint_ZH2" kp="10.0" kv="0.1" ctrlrange="-1.04 1.04"/> 
    <position joint="joint_YH2" kp="10.0" kv="0.1" ctrlrange="-1.04 1.04"/>
    <position joint="joint_ZQ3" kp="10.0" kv="0.1" ctrlrange="-2.6 2.6"/>
    <position joint="joint_YQ3" kp="10.0" kv="0.1" ctrlrange="-2.6 2.6"/>
    <position joint="joint_ZH3" kp="10.0" kv="0.1" ctrlrange="-2.6 2.6"/>
    <position joint="joint_YH3" kp="10.0" kv="0.1" ctrlrange="-2.6 2.6"/>
    <position joint="joint_ZQ4" kp="10.0" kv="0.1" ctrlrange="-2.5 -0.6"/>
    <position joint="joint_YQ4" kp="10.0" kv="0.1" ctrlrange="-2.5 -0.6"/>
    <position joint="joint_ZH4" kp="10.0" kv="0.1" ctrlrange="-2.5 -0.6"/>
    <position joint="joint_YH4" kp="10.0" kv="0.1" ctrlrange="-2.5 -0.6"/>
  </actuator> -->

  <actuator>
    <motor name="FL1" joint="joint_ZQ2"/>
    <motor name="FR1" joint="joint_YQ2"/>
    <motor name="RL1" joint="joint_ZH2"/>
    <motor name="RR1" joint="joint_YH2"/>
    <motor name="FL2" joint="joint_ZQ3"/>
    <motor name="FR2" joint="joint_YQ3"/>
    <motor name="RL2" joint="joint_ZH3"/>
    <motor name="RR2" joint="joint_YH3"/>
    <motor name="FL3" joint="joint_ZQ4"/>
    <motor name="FR3" joint="joint_YQ4"/>
    <motor name="RL3" joint="joint_ZH4"/>
    <motor name="RR3" joint="joint_YH4"/>
  </actuator>

  <sensor>
    <jointpos name="FR_hip_pos" joint="joint_YQ2" />
    <jointpos name="FR_thigh_pos" joint="joint_YQ3" />
    <jointpos name="FR_calf_pos" joint="joint_YQ4" />
    <jointpos name="FL_hip_pos" joint="joint_ZQ2" />
    <jointpos name="FL_thigh_pos" joint="joint_ZQ3" />
    <jointpos name="FL_calf_pos" joint="joint_ZQ4" />
    <jointpos name="RR_hip_pos" joint="joint_YH2" />
    <jointpos name="RR_thigh_pos" joint="joint_YH3" />
    <jointpos name="RR_calf_pos" joint="joint_YH4" />
    <jointpos name="RL_hip_pos" joint="joint_ZH2" />
    <jointpos name="RL_thigh_pos" joint="joint_ZH3" />
    <jointpos name="RL_calf_pos" joint="joint_ZH4" />

    <jointvel name="FR_hip_vel" joint="joint_YQ2" />
    <jointvel name="FR_thigh_vel" joint="joint_YQ3" />
    <jointvel name="FR_calf_vel" joint="joint_YQ4" />
    <jointvel name="FL_hip_vel" joint="joint_ZQ2" />
    <jointvel name="FL_thigh_vel" joint="joint_ZQ3" />
    <jointvel name="FL_calf_vel" joint="joint_ZQ4" />
    <jointvel name="RR_hip_vel" joint="joint_YH2" />
    <jointvel name="RR_thigh_vel" joint="joint_YH3" />
    <jointvel name="RR_calf_vel" joint="joint_YH4" />
    <jointvel name="RL_hip_vel" joint="joint_ZH2" />
    <jointvel name="RL_thigh_vel" joint="joint_ZH3" />
    <jointvel name="RL_calf_vel" joint="joint_ZH4" />

    <jointactuatorfrc name="FR_hip_torque" joint="joint_YQ2" noise="0.01" />
    <jointactuatorfrc name="FR_thigh_torque" joint="joint_YQ3" noise="0.01" />
    <jointactuatorfrc name="FR_calf_torque" joint="joint_YQ4" noise="0.01" />
    <jointactuatorfrc name="FL_hip_torque" joint="joint_ZQ2" noise="0.01" />
    <jointactuatorfrc name="FL_thigh_torque" joint="joint_ZQ3" noise="0.01" />
    <jointactuatorfrc name="FL_calf_torque" joint="joint_ZQ4" noise="0.01" />
    <jointactuatorfrc name="RR_hip_torque" joint="joint_YH2" noise="0.01" />
    <jointactuatorfrc name="RR_thigh_torque" joint="joint_YH3" noise="0.01" />
    <jointactuatorfrc name="RR_calf_torque" joint="joint_YH4" noise="0.01" />
    <jointactuatorfrc name="RL_hip_torque" joint="joint_ZH2" noise="0.01" />
    <jointactuatorfrc name="RL_thigh_torque" joint="joint_ZH3" noise="0.01" />
    <jointactuatorfrc name="RL_calf_torque" joint="joint_ZH4" noise="0.01" />

    <framequat name="imu_quat" objtype="site" objname="imu" />
    <gyro name="imu_gyro" site="imu" />
    <accelerometer name="imu_acc" site="imu" />
    
    <framepos name="frame_pos" objtype="site" objname="imu" />
    <framelinvel name="frame_vel" objtype="site" objname="imu" />
  </sensor>

</mujoco>
